Workbook

Sheet DATOS CUALITATIVOS
D3: CALIFACIONES CUALITATIVAS
D4: Aspecto a calificar | E4: Dato/Califiación
C5: Dato (Score) | D5: Score en Buro de Credito
C6: Dato (Años) | D6: Experiencia en el Giro (Empresa/Empresario)
C7: Califiación (0-100) | D7: Formalidad Financiera
C8: Califiación (0-100) | D8: Métricas ESG
D10: DETALLES DEL CRÉDITO
D11: Aspecto a calificar | E11: Dato
D12: Plazo
D13: Tasa de Interés
D14: Monto del Crédito
D15: Valor de Garantía

Sheet ESTADOS FINANCIEROS
C3: ESTADO DE RESULTADOS
D4: AÑO 1 | E4: AÑO 1 (%) | F4: AÑO 2 | G4: AÑO 2 (%) | H4: TRI / AÑO3 | I4: TRI / AÑO3 (%)
C6: VENTAS | E6: {=D6/D$6} | G6: {=F6/F$6} | I6: {=H6/H$6}
C7: Costos de Venta | E7: {=D7/D$6} | G7: {=F7/F$6} | I7: {=H7/H$6}
C8: Ut. Bruta | E8: {=D8/D$6} | G8: {=F8/F$6} | I8: {=H8/H$6}
C9: Gastos de Op. | E9: {=D9/D$6} | G9: {=F9/F$6} | I9: {=H9/H$6}
C10: UT. De operación | E10: {=D10/D$6} | G10: {=F10/F$6} | I10: {=H10/H$6}
C11: Gastos Fin. | E11: {=D11/D$6} | G11: {=F11/F$6} | I11: {=H11/H$6}
C12: Otros productos | E12: {=D12/D$6} | G12: {=F12/F$6} | I12: {=H12/H$6}
C13: Otros Gastos | E13: {=D13/D$6} | G13: {=F13/F$6} | I13: {=H13/H$6}
C14: UT. Antes de impuestos | E14: {=D14/D$6} | G14: {=F14/F$6} | I14: {=H14/H$6}
C15: Impuestos | E15: {=D15/D$6} | G15: {=F15/F$6} | I15: {=H15/H$6}
C16: UTILIDAD NETA | E16: {=D16/D$6} | G16: {=F16/F$6} | I16: {=H16/H$6}
C18: BALANCE GENERAL
D19: AÑO 1 | E19: AÑO 1 (%) | F19: AÑO 2 | G19: AÑO 2 (%) | H19: TRI / AÑO3 | I19: TRI / AÑO3 (%)
C21: Activo Circulante | E21: {=D21/D$34} | G21: {=F21/F$34} | I21: {=H21/H$34}
C22: Efectivo y Equivalentes | E22: {=D22/D$32} | G22: {=F22/F$32} | I22: {=H22/H$32}
C23: Inventarios | E23: {=D23/D$32} | G23: {=F23/F$32} | I23: {=H23/H$32}
C24: Clientes | E24: {=D24/D$32} | G24: {=F24/F$32} | I24: {=H24/H$32}
C25: Deudores Diversos | E25: {=D25/D$32} | G25: {=F25/F$32} | I25: {=H25/H$32}
C26: Activo Fijo | E26: {=D26/D$32} | G26: {=F26/F$32} | I26: {=H26/H$32}
C27: Terrenos y Edificios | E27: {=D27/D$32} | G27: {=F27/F$32} | I27: {=H27/H$32}
C28: Maquinaria y Equipo | E28: {=D28/D$32} | G28: {=F28/F$32} | I28: {=H28/H$32}
C29: Equipo de Transporte | E29: {=D29/D$32} | G29: {=F29/F$32} | I29: {=H29/H$32}
C30: Otros Activos | E30: {=D30/D$32} | G30: {=F30/F$32} | I30: {=H30/H$32}
C31: Intangibles (registro de marca) | E31: {=D31/D$32} | G31: {=F31/F$32} | I31: {=H31/H$32}
C32: ACTIVO TOTAL | E32: {=D32/D$32} | G32: {=F32/F$32} | I32: {=H32/H$32}
C34: Pasivo Circulante | E34: {=D34/D$45} | G34: {=F34/F$45} | I34: {=H34/H$45}
C35: Proveedores | E35: {=D35/D$45} | G35: {=F35/F$45} | I35: {=H35/H$45}
C36: Acreedores Div. | E36: {=D36/D$45} | G36: {=F36/F$45} | I36: {=H36/H$45}
C37: Docs. x pagar CP | E37: {=D37/D$45} | G37: {=F37/F$45} | I37: {=H37/H$45}
C38: Pasivo Largo Plazo | E38: {=D38/D$45} | G38: {=F38/F$45} | I38: {=H38/H$45}
C39: Docs. X pagar LP | E39: {=D39/D$45} | G39: {=F39/F$45} | I39: {=H39/H$45}
C40: Otros Pasivos | E40: {=D40/D$45} | G40: {=F40/F$45} | I40: {=H40/H$45}
C41: PASIVO TOTAL | E41: {=D41/D$45} | G41: {=F41/F$45} | I41: {=H41/H$45}
C42: Capital Social | E42: {=D42/D$45} | G42: {=F42/F$45} | I42: {=H42/H$45}
C43: Ut Ejercicios anterioes | E43: {=D43/D$45} | G43: {=F43/F$45} | I43: {=H43/H$45}
C44: CAPITAL CONTABLE | E44: {=D44/D$45} | G44: {=F44/F$45} | I44: {=H44/H$45}
C45: PASIVO TOTAL + CAPITAL CONTABLE | E45: {=D45/D$45} | G45: {=F45/F$45} | I45: {=H45/H$45}
C47: FLUJO DE EFECTIVO
...

Sheet ESTADOS DE CUENTA
C3: CUENTAS DE BANCO EN MONEDA LOCAL
E4: Banco 1 | I4: Banco 2 | M4: Banco 3 | Q4: TOTALES EN PESOS
C6: Año | D6: Mes | E6: Ingresos | F6: Egresos | G6: Saldos Promedio | I6: Ingresos | J6: Egresos | K6: Saldos Promedio | M6: Ingresos | N6: Egresos | O6: Saldos Promedio | Q6: Ingresos | R6: Egresos | S6: Saldos Promedio
C7: 2023 | D7: Enero | G7: {=E7-F7} -> 0
C8: 2023 | D8: Febrero | G8: {=E8-F8} -> 0
C9: 2023 | D9: Marzo | G9: {=E9-F9} -> 0
C10: 2023 | D10: Abril | G10: {=E10-F10} -> 0
C11: 2023 | D11: Mayo | G11: {=E11-F11} -> 0
C12: 2023 | D12: Junio | G12: {=E12-F12} -> 0
C13: 2023 | D13: Julio | G13: {=E13-F13} -> 0
C14: 2023 | D14: Agosto | G14: {=E14-F14} -> 0
C15: 2023 | D15: Septiembre | G15: {=E15-F15} -> 0
C16: 2023 | D16: Octubre | G16: {=E16-F16} -> 0
C17: 2023 | D17: Noviembre | G17: {=E17-F17} -> 0
C18: 2023 | D18: Diciembre | G18: {=E18-F18} -> 0
C19: TOTALES | E19: {=SUM(E7:E18)} -> 0 | F19: {=SUM(F7:F18)} -> 0 | G19: {=AVERAGE(G7:G18)} -> 0 | I19: {=SUM(I7:I18)} -> 0 | J19: {=SUM(J7:J18)} -> 0 | K19: {=AVERAGE(K7:K18)} | M19: {=SUM(M7:M18)} -> 0 | N19: {=SUM(N7:N18)} -> 0 | O19: {=AVERAGE(O7:O18)} | Q19: {=SUM(Q7:Q18)} -> 0 | R19: {=SUM(R7:R18)} -> 0 | S19: {=SUM(S7:S18)} -> 0
C21: CUENTAS DE BANCO EN MONEDA EXTRANJERA
E22: Banco 1 | I22: Banco 2 | M22: Banco 3 | Q22: TOTALES EN DOLARES
C24: Año | D24: Mes | E24: Ingresos | F24: Egresos | G24: Saldos Promedio | I24: Ingresos | J24: Egresos | K24: Saldos Promedio | M24: Ingresos | N24: Egresos | O24: Saldos Promedio | Q24: Ingresos | R24: Egresos | S24: Saldos Promedio
C25: 2023 | D25: Enero | Q25: {=E25+I25+M25} -> 0 | R25: {=F25+J25+N25} -> 0 | S25: {=G25+K25+O25} -> 0
C26: 2023 | D26: Febrero | Q26: {=E26+I26+M26} -> 0 | R26: {=F26+J26+N26} -> 0 | S26: {=G26+K26+O26} -> 0
C27: 2023 | D27: Marzo | Q27: {=E27+I27+M27} -> 0 | R27: {=F27+J27+N27} -> 0 | S27: {=G27+K27+O27} -> 0
C28: 2023 | D28: Abril | Q28: {=E28+I28+M28} -> 0 | R28: {=F28+J28+N28} -> 0 | S28: {=G28+K28+O28} -> 0
C29: 2023 | D29: Mayo | Q29: {=E29+I29+M29} -> 0 | R29: {=F29+J29+N29} -> 0 | S29: {=G29+K29+O29} -> 0
C30: 2023 | D30: Junio | Q30: {=E30+I30+M30} -> 0 | R30: {=F30+J30+N30} -> 0 | S30: {=G30+K30+O30} -> 0
C31: 2023 | D31: Julio | Q31: {=E31+I31+M31} -> 0 | R31: {=F31+J31+N31} -> 0 | S31: {=G31+K31+O31} -> 0
C32: 2023 | D32: Agosto | Q32: {=E32+I32+M32} -> 0 | R32: {=F32+J32+N32} -> 0 | S32: {=G32+K32+O32} -> 0
C33: 2023 | D33: Septiembre | Q33: {=E33+I33+M33} -> 0 | R33: {=F33+J33+N33} -> 0 | S33: {=G33+K33+O33} -> 0
C34: 2023 | D34: Octubre | Q34: {=E34+I34+M34} -> 0 | R34: {=F34+J34+N34} -> 0 | S34: {=G34+K34+O34} -> 0
C35: 2023 | D35: Noviembre | Q35: {=E35+I35+M35} -> 0 | R35: {=F35+J35+N35} -> 0 | S35: {=G35+K35+O35} -> 0
C36: 2023 | D36: Diciembre | Q36: {=E36+I36+M36} -> 0 | R36: {=F36+J36+N36} -> 0 | S36: {=G36+K36+O36} -> 0
C37: TOTALES | E37: {=SUM(E25:E36)} -> 0 | F37: {=SUM(F25:F36)} -> 0 | G37: {=AVERAGE(G25:G36)} | I37: {=SUM(I25:I36)} -> 0 | J37: {=SUM(J25:J36)} -> 0 | K37: {=AVERAGE(K25:K36)} | M37: {=SUM(M25:M36)} -> 0 | N37: {=SUM(N25:N36)} -> 0 | O37: {=AVERAGE(O25:O36)} | Q37: {=SUM(Q25:Q36)} -> 0 | R37: {=SUM(R25:R36)} -> 0 | S37: {=G37+K37+O37}
C39: TOTAL GENERAL
C41: CONVERSION USD A MX
C42: PESOS X DÓLAR: | E42: 1
F44: TOTAL CUENTAS EN DOLARES | J44: TOTAL CUENTAS EN PESOS | N44: TOTAL GENERAL
C45: Año | D45: Mes | E45: Ingresos | F45: Egresos | G45: Saldo Promedio | I45: Ingresos | J45: Egresos | K45: Saldo Promedio | M45: Ingresos | N45: Egresos | O45: Saldo Promedio
C46: {=C7} -> 2023 | D46: {=D7} -> Enero | E46: {=Q25*$E$42} -> 0 | F46: {=R25*$E$42} -> 0 | G46: {=S25*$E$42} -> 0 | I46: {=Q7} -> 0 | J46: {=R7} -> 0 | K46: {=S7} -> 0 | M46: {=E46+I46} -> 0 | N46: {=F46+J46} -> 0 | O46: {=G46+K46} -> 0
C47: {=C8} -> 2023 | D47: {=D8} -> Febrero | E47: {=Q26*$E$42} -> 0 | F47: {=R26*$E$42} -> 0 | G47: {=S26*$E$42} -> 0 | I47: {=Q8} -> 0 | J47: {=R8} -> 0 | K47: {=S8} -> 0 | M47: {=E47+I47} -> 0 | N47: {=F47+J47} -> 0 | O47: {=G47+K47} -> 0
C48: {=C9} -> 2023 | D48: {=D9} -> Marzo | E48: {=Q27*$E$42} -> 0 | F48: {=R27*$E$42} -> 0 | G48: {=S27*$E$42} -> 0 | I48: {=Q9} -> 0 | J48: {=R9} -> 0 | K48: {=S9} -> 0 | M48: {=E48+I48} -> 0 | N48: {=F48+J48} -> 0 | O48: {=G48+K48} -> 0
...

Sheet CRECIMIENTO
C3: SISTEMA DE VALORACIÓN CREDITICIA PARA "CRECIMIENTO"
C5: 1.0 PONDERACIÓN GENERAL | D5: PESO | E5: CALIFICACIÓN | F5: CALIFICACIÓN PONDERADA
C6: Liquidez | D6: 0.1 | E6: {=G16} | F6: {=D6*E6}
C7: Rentabilidad | D7: 0.2 | E7: {=G21} | F7: {=D7*E7}
C8: Apalancamiento | D8: 0.25 | E8: {=G26} | F8: {=D8*E8}
C9: Capacidad de Pago | D9: 0.35 | E9: {=G32} | F9: {=D9*E9}
C10: ESG + Buro + Perfil | D10: 0.1 | E10: {=G39} -> 30 | F10: {=D10*E10} -> 3
C11: TOTAL | D11: {=SUM(D6:D10)} -> 1 | F11: {=SUM(F6:F10)}
C13: 1.1 LIQUIDEZ | D13: PESO | E13: RESULTADO | F13: CALIFICACIÓN | G13: CALIFICACIÓN PONDERADA
C14: Liquidez Corriente | D14: 0.5 | E14: {=(('ESTADOS FINANCIEROS'!D21/'ESTADOS FINANCIEROS'!D34)*0.4)+(('ESTADOS FINANCIEROS'!F21/'ESTADOS FINANCIEROS'!F34)*0.4)+((('ESTADOS FINANCIEROS'!H21/'ESTADOS FINANCIEROS'!H34)*0.2))} | F14: {=IF(E14>3,30,IF(AND(E14>=1.5,E14<=2.5),100,IF(AND(E14>=1,E14<1.5),70,50)))} | G14: {=F14*D14}
C15: Capital de Trabajo / Ventas | D15: 0.5 | E15: {=((('ESTADOS FINANCIEROS'!D21-'ESTADOS FINANCIEROS'!D34)/'ESTADOS FINANCIEROS'!D6)*0.4)+((('ESTADOS FINANCIEROS'!F21-'ESTADOS FINANCIEROS'!F34)/'ESTADOS FINANCIEROS'!F6)*0.4)+((('ESTADOS FINANCIEROS'!H21-'ESTADOS FINANCIEROS'!H34)/'ESTADOS FINANCIEROS'!H6)*0.2)} | F15: {=IF(E15>0.1,100,IF(E15>=0,70,50))} | G15: {=F15*D15}
C16: TOTAL | D16: {=SUM(D14:D15)} -> 1 | G16: {=SUM(G14:G15)}
C18: 1.2 Rentabilidad | D18: PESO | E18: RESULTADO | F18: CALIFICACIÓN | G18: CALIFICACIÓN PONDERADA
C19: Margen EBITDA/Operación | D19: 0.5 | E19: {=(('ESTADOS FINANCIEROS'!D10/'ESTADOS FINANCIEROS'!D6)*0.4)+(('ESTADOS FINANCIEROS'!F10/'ESTADOS FINANCIEROS'!F6)*0.4)+(('ESTADOS FINANCIEROS'!H10/'ESTADOS FINANCIEROS'!H6)*0.2)} | F19: {=IF(E19>0.2,100,IF(E19>=0.1,70,50))} | G19: {=F19*D19}
C20: Crecimiento en Ventas | D20: 0.5 | E20: {=(('ESTADOS FINANCIEROS'!F6-'ESTADOS FINANCIEROS'!D6)/'ESTADOS FINANCIEROS'!F6)} | F20: {=IF(E20>0.05,100,IF(E20>=-0.05,70,IF(E20>=-0.15,50,30)))} | G20: {=F20*D20}
C21: TOTAL | D21: {=SUM(D19:D20)} -> 1 | G21: {=SUM(G19:G20)}
C23: 1.3 Apalancamiento | D23: PESO | E23: RESULTADO | F23: CALIFICACIÓN | G23: CALIFICACIÓN PONDERADA
C24: Deuda Neta /EBITDA | D24: 0.5 | E24: {=((('ESTADOS FINANCIEROS'!D40-'ESTADOS FINANCIEROS'!D21)/'ESTADOS FINANCIEROS'!D9)*0.4)+((('ESTADOS FINANCIEROS'!F40-'ESTADOS FINANCIEROS'!F21)/'ESTADOS FINANCIEROS'!F9)*0.4)+((('ESTADOS FINANCIEROS'!H40-'ESTADOS FINANCIEROS'!H21)/'ESTADOS FINANCIEROS'!H9)*0.2)} | F24: {=IF(E24>5,30,IF(E24<2.5,100,IF(E24<=4,70,50)))} | G24: {=F24*D24}
C25: Pasivo Total /Capital | D25: 0.5 | E25: {=(('ESTADOS FINANCIEROS'!D40/'ESTADOS FINANCIEROS'!D43)*0.4)+(('ESTADOS FINANCIEROS'!F40/'ESTADOS FINANCIEROS'!F43)*0.4)+(('ESTADOS FINANCIEROS'!H40/'ESTADOS FINANCIEROS'!H43)*0.2)} | F25: {=IF(E25>2.5,30,IF(E25<1,100,IF(E25<=2,70,50)))} | G25: {=F25*D25}
C26: TOTAL | D26: {=SUM(D24:D25)} -> 1 | G26: {=SUM(G24:G25)}
C28: 1.4 Capacidad de Pago | D28: PESO | E28: RESULTADO | F28: CALIFICACIÓN | G28: CALIFICACIÓN PONDERADA
C29: DSCR | D29: 0.5 | E29: {=(('ESTADOS FINANCIEROS'!D57/'ESTADOS FINANCIEROS'!D11)*0.4)+(('ESTADOS FINANCIEROS'!F57/'ESTADOS FINANCIEROS'!F11)*0.4)+(('ESTADOS FINANCIEROS'!H57/'ESTADOS FINANCIEROS'!H11)*0.2)} | F29: {=IF(E29>=1.5,100,IF(E29>=1.2,70,IF(E29>=1,50,30)))} | G29: {=F29*D29}
C30: Cobertura de Cuota Mensual | D30: 0.3 | E30: {=('ESTADOS FINANCIEROS'!D10*0.4)+('ESTADOS FINANCIEROS'!F10*0.4)+('ESTADOS FINANCIEROS'!H10*0.2)/PMT('DATOS CUALITATIVOS'!E13,'DATOS CUALITATIVOS'!E12,-'DATOS CUALITATIVOS'!E14)} | F30: {=IF(E30>=2,100,IF(E30>=1.5,70,IF(E30>=1.2,50,30)))} | G30: {=F30*D30}
C31: Deuda Total / Ventas | D31: 0.2 | E31: {=(('ESTADOS FINANCIEROS'!D41/'ESTADOS FINANCIEROS'!D6)*0.4)+(('ESTADOS FINANCIEROS'!F41/'ESTADOS FINANCIEROS'!F6)*0.4)+(('ESTADOS FINANCIEROS'!H41/'ESTADOS FINANCIEROS'!H6)*0.2)} | F31: {=IF(E31<0.3,100,IF(E31<=0.5,70,IF(E31<=0.7,50,30)))} | G31: {=F31*D31}
C32: TOTAL | D32: {=SUM(D29:D31)} -> 1 | G32: {=SUM(G29:G31)}
C34: 1.5 ESG + Buro + Perfil | D34: PESO | E34: RESULTADO | F34: CALIFICACIÓN | G34: CALIFICACIÓN PONDERADA
C35: Buro de Crédito | D35: 0.4 | E35: {='DATOS CUALITATIVOS'!E5} -> 0 | F35: {=IF(E35>=700,100,IF(E35>=650,70,IF(E35>=600,50,30)))} -> 30 | G35: {=F35*D35} -> 12
C36: Experiencia en el Giro del Empresario (AÑOS, CUALITATIVO) | D36: 0.2 | E36: {='DATOS CUALITATIVOS'!E6} -> 0 | F36: {=IF(E36>7,100,IF(E36>=4,70,IF(E36>=2,50,30)))} -> 30 | G36: {=F36*D36} -> 6
C37: Formalidad Financiera (CUALITATIVO) | D37: 0.2 | E37: {='DATOS CUALITATIVOS'!E7} -> 0 | F37: {=IF(E37>=80,100,IF(E37>=60,70,IF(E37>=40,50,30)))} -> 30 | G37: {=F37*D37} -> 6
C38: ESG (CUALITATIVO) | D38: 0.2 | E38: {='DATOS CUALITATIVOS'!E8} -> 0 | F38: {=IF(E38>=80,100,IF(E38>=60,70,IF(E38>=40,50,30)))} -> 30 | G38: {=F38*D38} -> 6
C39: TOTAL | D39: {=SUM(D35:D38)} -> 1 | G39: {=SUM(G35:G38)} -> 30
C41: 2.0 CALIFIACIÓN DE RIESGO
C42: CALIFIACIÓN PONDERADA | D42: {=F11}
C43: CALIFIACIÓN DE RIESGO | D43: {=IF(D42>=90,"A - Muy Bajo",IF(D42>=80,"B - Bajo",IF(D42>=70,"C - Medio",IF(D42>=60,"D - Medio Alto",IF(D42>=50,"E - Alto","F - Muy Alto")))))}

Sheet CRECIMIENTO KPIS
B2: RAZÓN | C2: BUENO (100) | D2: MEDIO (70) | E2: MALO (50) | F2: CRÍTICO (30) | H2: FORMULAS
B3: 1.1 LIQUIDEZ
B4: Liquidez Corriente | C4: 1.5 – 2.5 | D4: 1.0 – 1.49 | E4: <1.0 | F4: >3 | H4: Activo Circulante / Pasico CP
B5: Capital Trabajo / Ventas | C5: >10% | D5: 0% – 9.99% | E5: <0% | F5: — | H5: (Activo Circulante - Pasivo CP) / Ventas
B7: 1.2 RENTABILIDAD
B8: Margen EBITDA | C8: >20% | D8: 10% – 20% | E8: <10% | F8: — | H8: EBITDA / Ventas
B9: Crecimiento Ventas (2 años) | C9: >5% anual | D9: -5% a 5% | E9: -5% a -15% | F9: <-15% | H9: (Crecimiento1 + Crecimiento2)/2
B11: 1.3 APALANCAMIENTO
B12: Deuda Neta / EBITDA | C12: <2.5x | D12: 2.5x – 4.0x | E12: >4.0x | F12: >5x | H12: Deuda Neta / EBITDA
B13: Pasivo Total / Capital | C13: <1.0 | D13: 1.0 – 2.0 | E13: >2.0 | F13: >2.5 | H13: Deuda Total / Capital
B15: 1.4 CAPACIDAD DE PAGO
B16: DSCR | C16: ≥1.5 | D16: 1.2 – 1.49 | E16: <1.2 | F16: <1 | H16: Flujo Operativo / Servicio de Deuda
B17: Cobertura Cuota Mensual | C17: ≥2.0x | D17: 1.5x – 1.99x | E17: 1.2x – 1.49x | F17: <1.2x | H17: Flujo Mensual / Cuota Mensual
B18: Deuda Total / Ventas | C18: <30% | D18: 30% – 50% | E18: 50% – 70% | F18: >70% | H18: Deuda Total / Ventas
B20: 1.5 ESG + Buro + Perfil
B21: Buró de Crédito | C21: ≥700 | D21: 650 – 699 | E21: 600 – 649 | F21: <600 | H21: Score de Buro
B22: Experiencia en el Giro | C22: >7 años | D22: 4 – 7 años | E22: 2 – 3 años | F22: <2 años | H22: Años en el Giro
B23: Formalidad Financiera | C23: Total formalidad | D23: Parcial | E23: Básica | F23: Informal | H23: Escala Cualitativa (Total, Parcial, etc.)
B24: ESG (Cualitativo) | C24: ≥80 | D24: 60 – 79 | E24: 40 – 59 | F24: <40 | H24: Score ESG

Sheet DASHBOARD CREC.
C3: SCORE CREDITICIO | F3: {='CRECIMIENTO'!D42}
F4: {='CRECIMIENTO'!D43}
C6: 1.1 LIQUIDEZ | F6: 1.2 RENTABILIDAD | I6: 1.3 APALANCAMIENTO | L6: 1.4 CAPACIDAD DE PAGO | O6: 1.5 ESG + BURO + PERFIL
C7: {='CRECIMIENTO'!E6} | F7: {='CRECIMIENTO'!E7} | I7: {='CRECIMIENTO'!E8} | L7: {='CRECIMIENTO'!E9} | O7: {='CRECIMIENTO'!E10} -> 30
C45: 1.1 Razones de Liquidez | F45: PESO | G45: RESULTADO | H45: PUNTOS | I45: CLASIFICACIÓN
C46: Liquidez Corriente | F46: {='CRECIMIENTO'!D14} -> 0.5 | G46: {='CRECIMIENTO'!E14} | H46: {='CRECIMIENTO'!F14} | I46: {=IF(H46=100,"Bueno",IF(H46=70,"Medio",IF(H46=50,"Malo",IF(H46=30,"Crítico",""))))}
C47: Capital de Trabajo / Ventas | F47: {='CRECIMIENTO'!D15} -> 0.5 | G47: {='CRECIMIENTO'!E15} | H47: {='CRECIMIENTO'!F15} | I47: {=IF(H47=100,"Bueno",IF(H47=70,"Medio",IF(H47=50,"Malo",IF(H47=30,"Crítico",""))))}
C49: 1.2 Razones de Rentabilidad | F49: PESO | G49: RESULTADO | H49: PUNTOS | I49: CLASIFICACIÓN
C50: Margen EBITDA/Operación | F50: {='CRECIMIENTO'!D19} -> 0.5 | G50: {='CRECIMIENTO'!E19} | H50: {='CRECIMIENTO'!F19} | I50: {=IF(H50=100,"Bueno",IF(H50=70,"Medio",IF(H50=50,"Malo",IF(H50=30,"Crítico",""))))}
C51: Crecimiento en Ventas (2 Años) | F51: {='CRECIMIENTO'!D20} -> 0.5 | G51: {='CRECIMIENTO'!E20} | H51: {='CRECIMIENTO'!F20} | I51: {=IF(H51=100,"Bueno",IF(H51=70,"Medio",IF(H51=50,"Malo",IF(H51=30,"Crítico",""))))}
C53: 1.3 Razones de Apalancamiento | F53: PESO | G53: RESULTADO | H53: PUNTOS | I53: CLASIFICACIÓN
C54: Deuda Total /EBITDA | F54: {='CRECIMIENTO'!D24} -> 0.5 | G54: {='CRECIMIENTO'!E24} | H54: {='CRECIMIENTO'!F24} | I54: {=IF(H54=100,"Bueno",IF(H54=70,"Medio",IF(H54=50,"Malo",IF(H54=30,"Crítico",""))))}
C55: Deuda Total /Capital Contable | F55: {='CRECIMIENTO'!D25} -> 0.5 | G55: {='CRECIMIENTO'!E25} | H55: {='CRECIMIENTO'!F25} | I55: {=IF(H55=100,"Bueno",IF(H55=70,"Medio",IF(H55=50,"Malo",IF(H55=30,"Crítico",""))))}
C57: 1.4 Capacidad de Pago | F57: PESO | G57: RESULTADO | H57: PUNTOS | I57: CLASIFICACIÓN
C58: DSCR | F58: {='CRECIMIENTO'!D29} -> 0.5 | G58: {='CRECIMIENTO'!E29} | H58: {='CRECIMIENTO'!F29} | I58: {=IF(H58=100,"Bueno",IF(H58=70,"Medio",IF(H58=50,"Malo",IF(H58=30,"Crítico",""))))}
C59: Cobertura de Cuota Mensual | F59: {='CRECIMIENTO'!D30} -> 0.3 | G59: {='CRECIMIENTO'!E30} | H59: {='CRECIMIENTO'!F30} | I59: {=IF(H59=100,"Bueno",IF(H59=70,"Medio",IF(H59=50,"Malo",IF(H59=30,"Crítico",""))))}
C60: Deuda Total / Ventas | F60: {='CRECIMIENTO'!D31} -> 0.2 | G60: {='CRECIMIENTO'!E31} | H60: {='CRECIMIENTO'!F31} | I60: {=IF(H60=100,"Bueno",IF(H60=70,"Medio",IF(H60=50,"Malo",IF(H60=30,"Crítico",""))))}
C62: 1.5 ESG + Buro + Perfil | F62: PESO | G62: RESULTADO | H62: PUNTOS | I62: CLASIFICACIÓN
C63: Buro de Crédito | F63: {='CRECIMIENTO'!D35} -> 0.4 | G63: {='CRECIMIENTO'!E35} -> 0 | H63: {='CRECIMIENTO'!F35} -> 30 | I63: {=IF(H63=100,"Bueno",IF(H63=70,"Medio",IF(H63=50,"Malo",IF(H63=30,"Crítico",""))))} -> Crítico
C64: Experiencia | F64: {='CRECIMIENTO'!D36} -> 0.2 | G64: {='CRECIMIENTO'!E36} -> 0 | H64: {='CRECIMIENTO'!F36} -> 30 | I64: {=IF(H64=100,"Bueno",IF(H64=70,"Medio",IF(H64=50,"Malo",IF(H64=30,"Crítico",""))))} -> Crítico
C65: Formalidad | F65: {='CRECIMIENTO'!D37} -> 0.2 | G65: {='CRECIMIENTO'!E37} -> 0 | H65: {='CRECIMIENTO'!F37} -> 30 | I65: {=IF(H65=100,"Bueno",IF(H65=70,"Medio",IF(H65=50,"Malo",IF(H65=30,"Crítico",""))))} -> Crítico
C66: ESG | F66: {='CRECIMIENTO'!D38} -> 0.2 | G66: {='CRECIMIENTO'!E38} -> 0 | H66: {='CRECIMIENTO'!F38} -> 30 | I66: {=IF(H66=100,"Bueno",IF(H66=70,"Medio",IF(H66=50,"Malo",IF(H66=30,"Crítico",""))))} -> Crítico
C68: COMENTARIOS:
